<?xml version="1.0" ?>
<!-- =================================================================================== -->
<!-- |    This document was autogenerated by xacro from potential_fields/urdf/robot.urdf.xacro | -->
<!-- |    EDITING THIS FILE BY HAND IS NOT RECOMMENDED                                 | -->
<!-- =================================================================================== -->
<robot name="turtlebot">
  <!-- Turtle Links -->
  <link name="base_link">
    <visual>
      <geometry>
        <box size="0.15 0.15 0.15"/>
      </geometry>
      <material name="transparent_mat">
        <color rgba="0.8 0.8 0.8 0.5"/>
      </material>
    </visual>
    <collision>
      <geometry>
        <box size="0.15 0.15 0.15"/>
      </geometry>
      <!-- defaults to origin (0 0 0) relative to link frame -->
    </collision>
  </link>
  <link name="stem">
    <visual>
      <geometry>
        <cylinder length="1.5725" radius="0.047175"/>
      </geometry>
      <material name="grey_mat">
        <color rgba="0.128 0.128 0.128 1"/>
      </material>
    </visual>
    <collision>
      <geometry>
        <cylinder length="1.5725" radius="0.047175"/>
      </geometry>
    </collision>
  </link>
  <link name="wheel_stem">
    <visual>
      <geometry>
        <cylinder length="0.2775" radius="0.0225"/>
      </geometry>
      <material name="grey_mat">
        <color rgba="0.128 0.128 0.128 1"/>
      </material>
    </visual>
    <collision>
      <geometry>
        <cylinder length="0.2775" radius="0.0225"/>
      </geometry>
    </collision>
  </link>
  <link name="platform">
    <visual>
      <geometry>
        <cylinder length="0.078625" radius="0.770525"/>
      </geometry>
      <material name="green_mat">
        <color rgba="0 1 0.2 1"/>
      </material>
    </visual>
    <collision>
      <geometry>
        <cylinder length="0.078625" radius="0.770525"/>
      </geometry>
    </collision>
  </link>
  <link name="wheel">
    <visual>
      <geometry>
        <cylinder length="0.045" radius="0.15"/>
      </geometry>
      <material name="black_mat">
        <color rgba="1 0 0 1"/>
      </material>
    </visual>
    <collision>
      <geometry>
        <cylinder length="0.045" radius="0.15"/>
      </geometry>
    </collision>
  </link>
  <!-- Joints -->
  <joint name="base_to_stem" type="fixed">
    <parent link="base_link"/>
    <child link="stem"/>
    <origin xyz="0.0 0.0 0.86125"/>
  </joint>
  <joint name="stem_to_platform" type="continuous">
    <parent link="stem"/>
    <child link="platform"/>
    <axis xyz="0.0 1.0 0.0"/>
    <origin xyz="0.0 0.0 0.78625"/>
  </joint>
  <joint name="base_to_wheel_stem" type="continuous">
    <parent link="base_link"/>
    <child link="wheel_stem"/>
    <axis xyz="0.0 0.0 1.0"/>
    <origin xyz="0.0 0.0 -0.21375"/>
  </joint>
  <joint name="wheel_stem_to_wheel" type="continuous">
    <parent link="wheel_stem"/>
    <child link="wheel"/>
    <origin rpy="1.5707963267948966 0.0 0.0" xyz="0.0 0.0 -0.28875"/>
    <axis xyz="0.0 0.0 1.0"/>
  </joint>
</robot>
